Please run `conda env list` to see a list of all available environments. Use
`source activate <env>` to activate the environment '<env>'. 
Lmod has detected the following error: The following module(s) are unknown:
"cuda/cuda-11.3"

Please check the spelling or version number. Also try "module spider ..."
It is also possible your cache file is out-of-date; it may help to try:
  $ module --ignore_cache load "cuda/cuda-11.3"

Also make sure that all modulefiles written in TCL start with the string
#%Module




Currently Loaded Modules:
  1) anaconda/anaconda3

 


CommandNotFoundError: Your shell has not been properly configured to use 'conda deactivate'.
To initialize your shell, run

    $ conda init <SHELL_NAME>

Currently supported shells are:
  - bash
  - fish
  - tcsh
  - xonsh
  - zsh
  - powershell

See 'conda init --help' for more information and options.

IMPORTANT: You may need to close and restart your shell after running 'conda init'.


/home/amckinney/my-envs/autd/lib/python3.7/site-packages/gym/logger.py:30: UserWarning: [33mWARN: Box bound precision lowered by casting to float32[0m
  warnings.warn(colorize('%s: %s'%('WARN', msg % args), 'yellow'))
Traceback (most recent call last):
  File "./discrete/run/teacher/dungeon_quest_teacher_ddpg.py", line 64, in <module>
    run_training(config)
  File "/lustre/fs1/home/amckinney/Local_Neuro_Symbolic/discrete/lib/main.py", line 45, in run_training
    train_agent(config, agent, automaton, ap_extractor, rollout_buffer, logger, start_iter, run_name=run_name)
  File "/lustre/fs1/home/amckinney/Local_Neuro_Symbolic/discrete/lib/training.py", line 558, in train_agent
    target_agent = agent.create_target_agent(tau=config.tau)
  File "/lustre/fs1/home/amckinney/Local_Neuro_Symbolic/discrete/lib/agent/DDPG_Agent.py", line 401, in create_target_agent
    return AC_EasyTargetAgent(self, DDPG_Agent(self.input_shape, self.num_actions), tau=tau).to(self.device)
  File "/lustre/fs1/home/amckinney/Local_Neuro_Symbolic/discrete/lib/agent/AC_easy_target_agent.py", line 24, in __init__
    assert False
AssertionError

real	1m13.113s
user	0m12.751s
sys	0m6.625s
mv: cannot stat â€˜./test_output/test_output*â€™: No such file or directory
